Traceback (most recent call last):
  File "/Users/emily/opt/anaconda3/envs/eoda/lib/python3.11/site-packages/jupyter_cache/executors/utils.py", line 51, in single_nb_execution
    executenb(
  File "/Users/emily/opt/anaconda3/envs/eoda/lib/python3.11/site-packages/nbclient/client.py", line 1204, in execute
    return NotebookClient(nb=nb, resources=resources, km=km, **kwargs).execute()
           ^^^^^^^^^^^^^^^^^^^^^^^^^^^^^^^^^^^^^^^^^^^^^^^^^^^^^^^^^^^^^^^^^^^^^
  File "/Users/emily/opt/anaconda3/envs/eoda/lib/python3.11/site-packages/nbclient/util.py", line 84, in wrapped
    return just_run(coro(*args, **kwargs))
           ^^^^^^^^^^^^^^^^^^^^^^^^^^^^^^^
  File "/Users/emily/opt/anaconda3/envs/eoda/lib/python3.11/site-packages/nbclient/util.py", line 62, in just_run
    return loop.run_until_complete(coro)
           ^^^^^^^^^^^^^^^^^^^^^^^^^^^^^
  File "/Users/emily/opt/anaconda3/envs/eoda/lib/python3.11/asyncio/base_events.py", line 650, in run_until_complete
    return future.result()
           ^^^^^^^^^^^^^^^
  File "/Users/emily/opt/anaconda3/envs/eoda/lib/python3.11/contextlib.py", line 222, in __aexit__
    await self.gen.athrow(typ, value, traceback)
  File "/Users/emily/opt/anaconda3/envs/eoda/lib/python3.11/site-packages/nbclient/client.py", line 608, in async_setup_kernel
    yield
  File "/Users/emily/opt/anaconda3/envs/eoda/lib/python3.11/site-packages/nbclient/client.py", line 663, in async_execute
    await self.async_execute_cell(
  File "/Users/emily/opt/anaconda3/envs/eoda/lib/python3.11/site-packages/nbclient/client.py", line 965, in async_execute_cell
    await self._check_raise_for_error(cell, cell_index, exec_reply)
  File "/Users/emily/opt/anaconda3/envs/eoda/lib/python3.11/site-packages/nbclient/client.py", line 862, in _check_raise_for_error
    raise CellExecutionError.from_cell_and_msg(cell, exec_reply_content)
nbclient.exceptions.CellExecutionError: An error occurred while executing the following cell:
------------------
import gcdistance
help(gcdistance) 
------------------

[0;31m---------------------------------------------------------------------------[0m
[0;31mModuleNotFoundError[0m                       Traceback (most recent call last)
Cell [0;32mIn[1], line 1[0m
[0;32m----> 1[0m [38;5;28;01mimport[39;00m [38;5;21;01mgcdistance[39;00m
[1;32m      2[0m help(gcdistance) 

File [0;32m/Volumes/GoogleDrive/My Drive/WWU_Courses_Master/MACS401/EODA_Book/Earth_Ocean_Data_Analysis_MACS401/Notebooks/gcdistance.py:4[0m
[1;32m      1[0m [38;5;124;03m"""[39;00m
[1;32m      2[0m [38;5;124;03mA python module for computing great circle distance[39;00m
[1;32m      3[0m [38;5;124;03m"""[39;00m
[0;32m----> 4[0m [38;5;28;01mimport[39;00m [38;5;21;01mnumpy[39;00m [38;5;28;01mas[39;00m [38;5;21;01mnp[39;00m
[1;32m      6[0m [38;5;66;03m# approximate radius of Earth[39;00m
[1;32m      7[0m R [38;5;241m=[39m [38;5;241m6.371e6[39m

[0;31mModuleNotFoundError[0m: No module named 'numpy'
ModuleNotFoundError: No module named 'numpy'

